<?xml version="1.0" ?>
<!-- =================================================================================== -->
<!-- |    This document was autogenerated by xacro from dual_sia5d.xacro               | -->
<!-- |    EDITING THIS FILE BY HAND IS NOT RECOMMENDED                                 | -->
<!-- =================================================================================== -->
<robot name="dual_motoman_sia5d" xmlns:xacro="http://ros.org/wiki/xacro">
  <link name="base_link">
    <visual>
      <geometry>
        <box size="0.5 1.5 0.2"/>
      </geometry>
      <origin rpy="0 0 0" xyz="0 0 0.1"/>
      <material name="blue">
        <color rgba="0 0 0.8 1"/>
      </material>
    </visual>
    <collision>
      <geometry>
        <box size="1.5 0.5 0.2"/>
      </geometry>
      <origin rpy="0 0 0" xyz="0 0 0.1"/>
    </collision>
  </link>
  <link name="base_footprint">
  </link>
  <joint name="base_footprint_joint" type="fixed">
    <parent link="base_footprint"/>
    <child link="base_link"/>
    <origin xyz="0 0 0"/>
  </joint>
  <!--degrees to radians-->
  <link name="1_base_link">
    <visual>
      <origin rpy="0 0 0" xyz="0 0 0"/>
      <geometry>
        <mesh filename="package://motoman_sia5d_support/meshes/sia5d/visual/base.dae"/>
      </geometry>
    </visual>
    <collision>
      <origin rpy="0 0 0" xyz="0 0 0"/>
      <geometry>
        <mesh filename="package://motoman_sia5d_support/meshes/sia5d/collision/base.dae"/>
      </geometry>
    </collision>
  </link>
  <link name="1_link_s">
    <visual>
      <origin rpy="0 0 0" xyz="0 0 0"/>
      <geometry>
        <mesh filename="package://motoman_sia5d_support/meshes/sia5d/visual/link_s.dae"/>
      </geometry>
    </visual>
    <collision>
      <origin rpy="0 0 0" xyz="0 0 0"/>
      <geometry>
        <mesh filename="package://motoman_sia5d_support/meshes/sia5d/collision/link_s.dae"/>
      </geometry>
    </collision>
  </link>
  <joint name="1_joint_s" type="revolute">
    <origin rpy="0 0 0" xyz="0 0 0.31"/>
    <!--r=${90*deg}-->
    <parent link="1_base_link"/>
    <child link="1_link_s"/>
    <axis xyz="0 0 1"/>
    <limit effort="0" lower="-3.14159274" upper="3.14159274" velocity="3.4906586"/>
  </joint>
  <link name="1_link_l">
    <visual>
      <origin rpy="0 0 0" xyz="0 0 0"/>
      <geometry>
        <mesh filename="package://motoman_sia5d_support/meshes/sia5d/visual/link_l.dae"/>
      </geometry>
    </visual>
    <collision>
      <origin rpy="0 0 0" xyz="0 0 0"/>
      <geometry>
        <mesh filename="package://motoman_sia5d_support/meshes/sia5d/collision/link_l.dae"/>
      </geometry>
    </collision>
  </link>
  <joint name="1_joint_l" type="revolute">
    <origin rpy="0 0 0" xyz="0 0 0"/>
    <parent link="1_link_s"/>
    <child link="1_link_l"/>
    <axis xyz="0 1 0"/>
    <limit effort="0" lower="-1.91986223" upper="1.91986223" velocity="3.4906586"/>
  </joint>
  <link name="1_link_e">
    <visual>
      <origin rpy="0 0 0" xyz="0 0 0"/>
      <geometry>
        <mesh filename="package://motoman_sia5d_support/meshes/sia5d/visual/link_e.dae"/>
      </geometry>
    </visual>
    <collision>
      <origin rpy="0 0 0" xyz="0 0 0"/>
      <geometry>
        <mesh filename="package://motoman_sia5d_support/meshes/sia5d/collision/link_e.dae"/>
      </geometry>
    </collision>
  </link>
  <joint name="1_joint_e" type="revolute">
    <origin rpy="0 0 0" xyz="0 0 0.27"/>
    <parent link="1_link_l"/>
    <child link="1_link_e"/>
    <axis xyz="0 0 1"/>
    <limit effort="0" lower="-2.96705981" upper="2.96705981" velocity="3.4906586"/>
  </joint>
  <link name="1_link_u">
    <visual>
      <origin rpy="0 0 0" xyz="0 0 0"/>
      <geometry>
        <mesh filename="package://motoman_sia5d_support/meshes/sia5d/visual/link_u.dae"/>
      </geometry>
    </visual>
    <collision>
      <origin rpy="0 0 0" xyz="0 0 0"/>
      <geometry>
        <mesh filename="package://motoman_sia5d_support/meshes/sia5d/collision/link_u.dae"/>
      </geometry>
    </collision>
  </link>
  <joint name="1_joint_u" type="revolute">
    <origin rpy="0 0 0" xyz="0.085 0 0"/>
    <parent link="1_link_e"/>
    <child link="1_link_u"/>
    <axis xyz="0 -1 0"/>
    <limit effort="0" lower="-1.57079637" upper="2.007128695" velocity="3.4906586"/>
  </joint>
  <link name="1_link_r">
    <visual>
      <origin rpy="0 0 0" xyz="0 0 0"/>
      <geometry>
        <mesh filename="package://motoman_sia5d_support/meshes/sia5d/visual/link_r.dae"/>
      </geometry>
    </visual>
    <collision>
      <origin rpy="0 0 0" xyz="0 0 0"/>
      <geometry>
        <mesh filename="package://motoman_sia5d_support/meshes/sia5d/collision/link_r.dae"/>
      </geometry>
    </collision>
  </link>
  <joint name="1_joint_r" type="revolute">
    <origin rpy="0 0 0" xyz="0.27 0 0.06"/>
    <parent link="1_link_u"/>
    <child link="1_link_r"/>
    <axis xyz="-1 0 0"/>
    <limit effort="0" lower="-1.57079637" upper="1.57079637" velocity="3.4906586"/>
  </joint>
  <link name="1_link_b">
    <visual>
      <origin rpy="0 0 0" xyz="0 0 0"/>
      <geometry>
        <mesh filename="package://motoman_sia5d_support/meshes/sia5d/visual/link_b.dae"/>
      </geometry>
    </visual>
    <collision>
      <origin rpy="0 0 0" xyz="0 0 0"/>
      <geometry>
        <mesh filename="package://motoman_sia5d_support/meshes/sia5d/collision/link_b.dae"/>
      </geometry>
    </collision>
  </link>
  <joint name="1_joint_b" type="revolute">
    <origin rpy="0 0 0" xyz="0 0 0"/>
    <parent link="1_link_r"/>
    <child link="1_link_b"/>
    <axis xyz="0 -1 0"/>
    <limit effort="0" lower="-1.91986223" upper="1.91986223" velocity="4.01425739"/>
  </joint>
  <link name="1_link_t">
    <visual>
      <origin rpy="0 0 0" xyz="0 0 0"/>
      <geometry>
        <mesh filename="package://motoman_sia5d_support/meshes/sia5d/visual/link_t.dae"/>
      </geometry>
    </visual>
    <collision>
      <origin rpy="0 0 0" xyz="0 0 0"/>
      <geometry>
        <mesh filename="package://motoman_sia5d_support/meshes/sia5d/collision/link_t.dae"/>
      </geometry>
    </collision>
  </link>
  <joint name="1_joint_t" type="revolute">
    <origin rpy="0 0 0" xyz="0.134 0 0"/>
    <parent link="1_link_b"/>
    <child link="1_link_t"/>
    <axis xyz="-1 0 0"/>
    <limit effort="0" lower="-1.57079637" upper="1.57079637" velocity="6.10865255"/>
  </joint>
  <link name="1_tool0"/>
  <joint name="1_link_t-tool0" type="fixed">
    <origin rpy="-1.57079637 -1.57079637 -1.57079637" xyz="0.011 0 0"/>
    <parent link="1_link_t"/>
    <child link="1_tool0"/>
  </joint>
  <!-- ROS base_link (via base_link) to Motoman Robot (not Base) Frame transform -->
  <link name="1_base"/>
  <joint name="1_base_link-base" type="fixed">
    <origin rpy="0 0 0" xyz="0 0 0.310"/>
    <parent link="1_base_link"/>
    <child link="1_base"/>
  </joint>
  <link name="2_base_link">
    <visual>
      <origin rpy="0 0 0" xyz="0 0 0"/>
      <geometry>
        <mesh filename="package://motoman_sia5d_support/meshes/sia5d/visual/base.dae"/>
      </geometry>
    </visual>
    <collision>
      <origin rpy="0 0 0" xyz="0 0 0"/>
      <geometry>
        <mesh filename="package://motoman_sia5d_support/meshes/sia5d/collision/base.dae"/>
      </geometry>
    </collision>
  </link>
  <link name="2_link_s">
    <visual>
      <origin rpy="0 0 0" xyz="0 0 0"/>
      <geometry>
        <mesh filename="package://motoman_sia5d_support/meshes/sia5d/visual/link_s.dae"/>
      </geometry>
    </visual>
    <collision>
      <origin rpy="0 0 0" xyz="0 0 0"/>
      <geometry>
        <mesh filename="package://motoman_sia5d_support/meshes/sia5d/collision/link_s.dae"/>
      </geometry>
    </collision>
  </link>
  <joint name="2_joint_s" type="revolute">
    <origin rpy="0 0 0" xyz="0 0 0.31"/>
    <!--r=${90*deg}-->
    <parent link="2_base_link"/>
    <child link="2_link_s"/>
    <axis xyz="0 0 1"/>
    <limit effort="0" lower="-3.14159274" upper="3.14159274" velocity="3.4906586"/>
  </joint>
  <link name="2_link_l">
    <visual>
      <origin rpy="0 0 0" xyz="0 0 0"/>
      <geometry>
        <mesh filename="package://motoman_sia5d_support/meshes/sia5d/visual/link_l.dae"/>
      </geometry>
    </visual>
    <collision>
      <origin rpy="0 0 0" xyz="0 0 0"/>
      <geometry>
        <mesh filename="package://motoman_sia5d_support/meshes/sia5d/collision/link_l.dae"/>
      </geometry>
    </collision>
  </link>
  <joint name="2_joint_l" type="revolute">
    <origin rpy="0 0 0" xyz="0 0 0"/>
    <parent link="2_link_s"/>
    <child link="2_link_l"/>
    <axis xyz="0 1 0"/>
    <limit effort="0" lower="-1.91986223" upper="1.91986223" velocity="3.4906586"/>
  </joint>
  <link name="2_link_e">
    <visual>
      <origin rpy="0 0 0" xyz="0 0 0"/>
      <geometry>
        <mesh filename="package://motoman_sia5d_support/meshes/sia5d/visual/link_e.dae"/>
      </geometry>
    </visual>
    <collision>
      <origin rpy="0 0 0" xyz="0 0 0"/>
      <geometry>
        <mesh filename="package://motoman_sia5d_support/meshes/sia5d/collision/link_e.dae"/>
      </geometry>
    </collision>
  </link>
  <joint name="2_joint_e" type="revolute">
    <origin rpy="0 0 0" xyz="0 0 0.27"/>
    <parent link="2_link_l"/>
    <child link="2_link_e"/>
    <axis xyz="0 0 1"/>
    <limit effort="0" lower="-2.96705981" upper="2.96705981" velocity="3.4906586"/>
  </joint>
  <link name="2_link_u">
    <visual>
      <origin rpy="0 0 0" xyz="0 0 0"/>
      <geometry>
        <mesh filename="package://motoman_sia5d_support/meshes/sia5d/visual/link_u.dae"/>
      </geometry>
    </visual>
    <collision>
      <origin rpy="0 0 0" xyz="0 0 0"/>
      <geometry>
        <mesh filename="package://motoman_sia5d_support/meshes/sia5d/collision/link_u.dae"/>
      </geometry>
    </collision>
  </link>
  <joint name="2_joint_u" type="revolute">
    <origin rpy="0 0 0" xyz="0.085 0 0"/>
    <parent link="2_link_e"/>
    <child link="2_link_u"/>
    <axis xyz="0 -1 0"/>
    <limit effort="0" lower="-1.57079637" upper="2.007128695" velocity="3.4906586"/>
  </joint>
  <link name="2_link_r">
    <visual>
      <origin rpy="0 0 0" xyz="0 0 0"/>
      <geometry>
        <mesh filename="package://motoman_sia5d_support/meshes/sia5d/visual/link_r.dae"/>
      </geometry>
    </visual>
    <collision>
      <origin rpy="0 0 0" xyz="0 0 0"/>
      <geometry>
        <mesh filename="package://motoman_sia5d_support/meshes/sia5d/collision/link_r.dae"/>
      </geometry>
    </collision>
  </link>
  <joint name="2_joint_r" type="revolute">
    <origin rpy="0 0 0" xyz="0.27 0 0.06"/>
    <parent link="2_link_u"/>
    <child link="2_link_r"/>
    <axis xyz="-1 0 0"/>
    <limit effort="0" lower="-1.57079637" upper="1.57079637" velocity="3.4906586"/>
  </joint>
  <link name="2_link_b">
    <visual>
      <origin rpy="0 0 0" xyz="0 0 0"/>
      <geometry>
        <mesh filename="package://motoman_sia5d_support/meshes/sia5d/visual/link_b.dae"/>
      </geometry>
    </visual>
    <collision>
      <origin rpy="0 0 0" xyz="0 0 0"/>
      <geometry>
        <mesh filename="package://motoman_sia5d_support/meshes/sia5d/collision/link_b.dae"/>
      </geometry>
    </collision>
  </link>
  <joint name="2_joint_b" type="revolute">
    <origin rpy="0 0 0" xyz="0 0 0"/>
    <parent link="2_link_r"/>
    <child link="2_link_b"/>
    <axis xyz="0 -1 0"/>
    <limit effort="0" lower="-1.91986223" upper="1.91986223" velocity="4.01425739"/>
  </joint>
  <link name="2_link_t">
    <visual>
      <origin rpy="0 0 0" xyz="0 0 0"/>
      <geometry>
        <mesh filename="package://motoman_sia5d_support/meshes/sia5d/visual/link_t.dae"/>
      </geometry>
    </visual>
    <collision>
      <origin rpy="0 0 0" xyz="0 0 0"/>
      <geometry>
        <mesh filename="package://motoman_sia5d_support/meshes/sia5d/collision/link_t.dae"/>
      </geometry>
    </collision>
  </link>
  <joint name="2_joint_t" type="revolute">
    <origin rpy="0 0 0" xyz="0.134 0 0"/>
    <parent link="2_link_b"/>
    <child link="2_link_t"/>
    <axis xyz="-1 0 0"/>
    <limit effort="0" lower="-1.57079637" upper="1.57079637" velocity="6.10865255"/>
  </joint>
  <link name="2_tool0"/>
  <joint name="2_link_t-tool0" type="fixed">
    <origin rpy="-1.57079637 -1.57079637 -1.57079637" xyz="0.011 0 0"/>
    <parent link="2_link_t"/>
    <child link="2_tool0"/>
  </joint>
  <!-- ROS base_link (via base_link) to Motoman Robot (not Base) Frame transform -->
  <link name="2_base"/>
  <joint name="2_base_link-base" type="fixed">
    <origin rpy="0 0 0" xyz="0 0 0.310"/>
    <parent link="2_base_link"/>
    <child link="2_base"/>
  </joint>
  <joint name="1_base_joint" type="fixed">
    <parent link="base_link"/>
    <child link="1_base_link"/>
    <origin xyz="0 0.5 0.2"/>
  </joint>
  <joint name="2_base_joint" type="fixed">
    <parent link="base_link"/>
    <child link="2_base_link"/>
    <origin xyz="0 -0.5 0.2"/>
  </joint>
</robot>

