<?xml version="1.0" ?>
<!-- =================================================================================== -->
<!-- |    This document was autogenerated by xacro from src/exam_task_1/urdf/exam.xacro | -->
<!-- |    EDITING THIS FILE BY HAND IS NOT RECOMMENDED                                 | -->
<!-- =================================================================================== -->
<robot name="five_wheeler" xmlns:xacro="http://www.ros.org/wiki/xacro">
  <material name="black">
    <color rgba="0 0 0 1"/>
  </material>
  <material name="white">
    <color rgba="1 1 1 1"/>
  </material>
  <link name="base_link">
    <visual>
      <geometry>
        <box size="0.8 0.5  0.2"/>
      </geometry>
      <origin rpy="0 0 0" xyz="0 0 0.2"/>
      <material name="white"/>
    </visual>
    <collision>
      <geometry>
        <box size="0.8 0.2  0.5"/>
      </geometry>
      <origin rpy="0 0 0" xyz="0 0 0.2"/>
    </collision>
    <inertial>
      <mass value="10"/>
      <inertia ixx="1.0" ixy="0.0" ixz="0.0" iyy="1.0" iyz="0.0" izz="1.0"/>
    </inertial>
  </link>
  <link name="left_front_wheel">
    <visual>
      <geometry>
        <cylinder length="0.05" radius="0.2"/>
      </geometry>
      <origin rpy="0 1.57079632679 0" xyz="0.025 0 0"/>
      <material name="black"/>
    </visual>
    <collision>
      <geometry>
        <cylinder length="0.05" radius="0.2"/>
      </geometry>
      <origin rpy="0 1.57079632679 0" xyz="0.025 0 0"/>
    </collision>
    <inertial>
      <mass value="10"/>
      <inertia ixx="1.0" ixy="0.0" ixz="0.0" iyy="1.0" iyz="0.0" izz="1.0"/>
    </inertial>
  </link>
  <joint name="base_to_left_front_wheel" type="continuous">
    <parent link="base_link"/>
    <child link="left_front_wheel"/>
    <origin rpy="0 0 1.57079632679" xyz="0.3 0.25 0.2"/>
  </joint>
  <link name="left_back_wheel">
    <visual>
      <geometry>
        <cylinder length="0.05" radius="0.2"/>
      </geometry>
      <origin rpy="0 1.57079632679 0" xyz="0.025 0 0"/>
      <material name="black"/>
    </visual>
    <collision>
      <geometry>
        <cylinder length="0.05" radius="0.2"/>
      </geometry>
      <origin rpy="0 1.57079632679 0" xyz="0.025 0 0"/>
    </collision>
    <inertial>
      <mass value="10"/>
      <inertia ixx="1.0" ixy="0.0" ixz="0.0" iyy="1.0" iyz="0.0" izz="1.0"/>
    </inertial>
  </link>
  <joint name="base_to_right_front_wheel" type="continuous">
    <parent link="base_link"/>
    <child link="left_back_wheel"/>
    <origin rpy="0 0 1.57079632679" xyz="-0.3 0.25 0.2"/>
  </joint>
  <link name="right_front_wheel">
    <visual>
      <geometry>
        <cylinder length="0.05" radius="0.2"/>
      </geometry>
      <origin rpy="0 1.57079632679 0" xyz="-0.025 0 0"/>
      <material name="black"/>
    </visual>
    <collision>
      <geometry>
        <cylinder length="0.05" radius="0.2"/>
      </geometry>
      <origin rpy="0 1.57079632679 0" xyz="-0.025 0 0"/>
    </collision>
    <inertial>
      <mass value="10"/>
      <inertia ixx="1.0" ixy="0.0" ixz="0.0" iyy="1.0" iyz="0.0" izz="1.0"/>
    </inertial>
  </link>
  <joint name="base_to_left_back_wheel" type="continuous">
    <parent link="base_link"/>
    <child link="right_front_wheel"/>
    <origin rpy="0 0 1.57079632679" xyz="0.3 -0.25 0.2"/>
  </joint>
  <link name="right_back_wheel">
    <visual>
      <geometry>
        <cylinder length="0.05" radius="0.2"/>
      </geometry>
      <origin rpy="0 1.57079632679 0" xyz="-0.025 0 0"/>
      <material name="black"/>
    </visual>
    <collision>
      <geometry>
        <cylinder length="0.05" radius="0.2"/>
      </geometry>
      <origin rpy="0 1.57079632679 0" xyz="-0.025 0 0"/>
    </collision>
    <inertial>
      <mass value="10"/>
      <inertia ixx="1.0" ixy="0.0" ixz="0.0" iyy="1.0" iyz="0.0" izz="1.0"/>
    </inertial>
  </link>
  <joint name="base_to_right_back_wheel" type="continuous">
    <parent link="base_link"/>
    <child link="right_back_wheel"/>
    <origin rpy="0 0 1.57079632679" xyz="-0.3 -0.25 0.2"/>
  </joint>
  <link name="front_extension">
    <visual>
      <geometry>
        <box size="0.3 0.225  0.2"/>
      </geometry>
      <origin rpy="0 0 0" xyz="0.15 0.1125 0"/>
      <material name="white"/>
    </visual>
    <collision>
      <geometry>
        <box size="0.3 0.225  0.2"/>
      </geometry>
      <origin rpy="0 0 0" xyz="0.15 0.1125 0"/>
    </collision>
    <inertial>
      <mass value="10"/>
      <inertia ixx="1.0" ixy="0.0" ixz="0.0" iyy="1.0" iyz="0.0" izz="1.0"/>
    </inertial>
  </link>
  <joint name="base_to_front extension" type="fixed">
    <parent link="base_link"/>
    <child link="front_extension"/>
    <origin xyz="0.4 -0.25 0.2"/>
  </joint>
  <link name="front_wheel">
    <visual>
      <geometry>
        <cylinder length="0.05" radius="0.2"/>
      </geometry>
      <origin rpy="0 1.57079632679 0" xyz="0.025 0 0"/>
      <material name="black"/>
    </visual>
    <collision>
      <geometry>
        <cylinder length="0.05" radius="0.2"/>
      </geometry>
      <origin rpy="0 1.57079632679 0" xyz="0.025 0 0"/>
    </collision>
    <inertial>
      <mass value="10"/>
      <inertia ixx="1.0" ixy="0.0" ixz="0.0" iyy="1.0" iyz="0.0" izz="1.0"/>
    </inertial>
  </link>
  <joint name="extension_to_front_wheel" type="continuous">
    <parent link="front_extension"/>
    <child link="front_wheel"/>
    <origin rpy="0 0 1.57079632679" xyz="0.25 0.225 0"/>
  </joint>
  <link name="base_footprint"> 
  </link>
  <joint name="base_footprint_to_base" type="fixed">
    <parent link="base_footprint"/>
    <child link="base_link"/>
  </joint>
</robot>

